### Por Que o Erro Aconteceu?
- **UnboundLocalError: 'pd'**: O erro ocorreu porque o m√≥dulo `pandas` (importado como `pd`) n√£o foi importado corretamente no script que voc√™ est√° usando. Isso pode ter acontecido devido a uma omiss√£o na importa√ß√£o ou a um erro de sintaxe que desativou a linha `import pandas as pd` (ex.: coment√°rio acidental ou m√° formata√ß√£o).
- **Impacto**: O script falhou ao tentar carregar o arquivo `PREDICTIONS_CSV` com `pd.read_csv()`, parando o workflow com `exit code 9`.

### Corre√ß√µes Aplicadas
1. **Importa√ß√£o Expl√≠cita**: Garanti que `import pandas as pd` esteja no in√≠cio do script, corrigindo o problema de escopo.
2. **Importa√ß√£o de csv**: Inclu√≠ `import csv` para suportar `csv.writer`.
3. **Robustez**: Adicionei verifica√ß√µes de exist√™ncia de arquivos e tratamento de exce√ß√µes com logs detalhados para evitar falhas silenciosas.

### A√ß√µes Adicionais
1. **Substitui√ß√£o do Script**:
   - Fa√ßa o download do script acima e substitua `scripts/calibrate_probs.py` no seu reposit√≥rio GitHub (`https://github.com/gabrielfalchetti/loteca-framework`).
   - Commit a mudan√ßa:
     ```bash
     git add scripts/calibrate_probs.py
     git commit -m "Fix calibrate_probs.py: Add missing pandas and csv imports"
     git push origin main
     ```

2. **Teste o Workflow**:
   - No GitHub, v√° para a aba "Actions", clique em "Run workflow" e execute manualmente.
   - Verifique os logs do step `26 Apply calibration`. O erro `UnboundLocalError` deve desaparecer.

3. **Confirma√ß√£o**: Se o teste passar, o workflow continuar√°. Se outro erro surgir (ex.: arquivo vazio), cole o log completo.
4. **Expans√£o**: Com isso resolvido, podemos adicionar mais valida√ß√µes ou ajustar o calibrador para Dirichlet (Kull et al., 2019).

O que acha? Quer prosseguir com a substitui√ß√£o e teste, ou precisa de mais ajuda? üöÄ